<?xml version="1.0"?>

<robot
  xmlns:sensor="http://playerstage.sourceforge.net/gazebo/xmlschema/#sensor"
  xmlns:controller="http://playerstage.sourceforge.net/gazebo/xmlschema/#controller"
  xmlns:interface="http://playerstage.sourceforge.net/gazebo/xmlschema/#interface">
    
  <macro name="eklavya_support_bar" params="suffix parent length *origin">
	<joint type="fixed" name="${parent}_support_bar_${suffix}_joint">
      <insert_block name="origin" />
      <parent link="${parent}"/>
      <child link="${parent}_support_bar_${suffix}"/>
    </joint>
    
    <link name="${parent}_support_bar_${suffix}">  
      <origin rpy="0 0 0" xyz="0 0 0"/>
      <inertial>
        <mass value="2.01" />
        <inertia ixx="1" ixy="0.0" ixz="0.0" iyy="1" iyz="0.0" izz="1"/>
      </inertial>
      <collision >
        <geometry>
          <box size=".03 .03 ${length}"/>
        </geometry>
      </collision>
      <visual >
	    <geometry>
          <box size=".03 .03 ${length}"/>
        </geometry>
        <material name="White"/>
      </visual>
    </link>
 </macro>
 
 
 <macro name="castor_support" params="suffix parent *origin">
	<joint type="fixed" name="${parent}_castor_support_${suffix}_joint">
	  <insert_block name="origin" />
      <parent link="${parent}"/>
      <child link="${parent}_castor_support_${suffix}_link"/>
    </joint>
    <link name="${parent}_castor_support_${suffix}_link">
      <origin rpy="0 0 0" xyz="0 0 0"/>
      <inertial>
        <mass value="0.01" />
        <inertia ixx="1" ixy="0.0" ixz="0.0" iyy="1" iyz="0.0" izz="1"/>
      </inertial>
      <collision name='extrusion_collision'>
        <geometry>
          <box size=".2 .1 .02"/>
        </geometry>
      </collision>
      <visual name='extrusion_visual'>
        <geometry>
          <box size=".2 .1 .02"/>
        </geometry>
        <material name="Blue"/>
      </visual>
    </link>
 </macro>
 
 <macro name="caster_support_hinge" params="suffix parent *origin">
	<joint name="${parent}_caster_support_hinge_${suffix}_joint" type="continuous">
      <insert_block name="origin" />
      <parent link="${parent}" />
      <child link="${parent}_caster_support_hinge_${suffix}_link"/>

      <axis xyz="0 0 1" />
      <anchor xyz="0.01 0 0" />
      <limit effort="100" velocity="100" k_velocity="0" />
      <joint_properties damping="0.0" friction="0.0" />
    </joint>

    <transmission type="pr2_mechanism_model/SimpleTransmission" name="base_caster_support_trans">
      <actuator name="${parent}_caster_support_hinge_${suffix}_motor" />
      <joint name="${parent}_caster_support_hinge_${suffix}_joint" />
      <mechanicalReduction>1.0</mechanicalReduction>
    </transmission>

    <link name="${parent}_caster_support_hinge_${suffix}_link">
      <inertial>
        <mass value="1"/>
        <origin xyz="0 0 0" />
        <inertia ixx="0.00375" ixy="0.0" ixz="0.0"
          iyy="0.00375" iyz="0.0"
          izz="0.00375" />
      </inertial>

      <visual>
        <eklavya_castor_support_link_mesh />
      </visual>

      <collision>
        <eklavya_castor_support_link_mesh />
      </collision>

    </link>
</macro>


<macro name="caster_wheel" params="suffix parent *origin">
	  
	  <joint name="${parent}_caster_wheel_${suffix}_joint" type="continuous">
      <insert_block name="origin" />
      <parent link="${parent}_caster_support_hinge_${suffix}_link" />
      <child link="${parent}_caster_wheel_${suffix}_link" />

      <axis xyz="0 1 0" />
      <anchor xyz="0 0 0" />
      <limit effort="100" velocity="100" k_velocity="0" />
      <joint_properties damping="0.0" friction="0.0" />
    </joint>

    <transmission type="pr2_mechanism_model/SimpleTransmission" name="caster_wheel_trans">
      <actuator name="${parent}_caster_wheel_${suffix}_motor" />
      <joint name="${parent}_caster_wheel_${suffix}_joint" />
      <mechanicalReduction>1.0</mechanicalReduction>
    </transmission>

    <link name="${parent}_caster_wheel_${suffix}_link">
      <inertial>
        <mass value="1" /> 
        <origin xyz="0 0 0" rpy="0 0 0" />
        <inertia  ixx="0.003" ixy="0.0" ixz="0.0"
          iyy="0.00581" iyz="0.0"
          izz="0.003" />
      </inertial>

      <visual>
        <eklavya_castor_wheel_link_mesh />
      </visual>

      <collision>
        <eklavya_castor_wheel_link_mesh />
      </collision>
    </link>
    <gazebo_eklavya_castor_wheel_link_surface suffix="${suffix}" parent="${parent}" />
</macro>

</robot>
