<?xml version="1.0" ?>
<!-- =================================================================================== -->
<!-- |    This document was autogenerated by xacro from eklavya.urdf.xacro             | -->
<!-- |    EDITING THIS FILE BY HAND IS NOT RECOMMENDED                                 | -->
<!-- =================================================================================== -->
<robot name="eklavya" xmlns:controller="http://playerstage.sourceforge.net/gazebo/xmlschema/#controller" xmlns:interface="http://playerstage.sourceforge.net/gazebo/xmlschema/#interface" xmlns:sensor="http://playerstage.sourceforge.net/gazebo/xmlschema/#sensor" xmlns:xacro="http://ros.org/wiki/xacro">
  <!--<include filename="$(find eklavya_description)/urdf/eklavya_hardware.urdf.xacro" />-->
  <!-- <include filename="$(find eklavya_description)/urdf/eklavya_calibration.xacro" />
  <include filename="$(find eklavya_description)/urdf/eklavya_kinect.urdf.xacro" />-->
  <!-- Body of Bot, with plates, standoffs and Create (including sim sensors) -->
  <link name="base_link">
    <pose>0 0 .375 0 0 3.14</pose>
    <inertial>
      <mass value="0.0001"/>
      <origin xyz="0 0 0"/>
      <inertia ixx="0.0001" ixy="0.0" ixz="0.0" iyy="0.0001" iyz="0.0" izz="0.0001"/>
    </inertial>
    <collision name="collision">
      <geometry>
        <box size=".55 .55 .55"/>
      </geometry>
    </collision>
    <visual name="visual">
      <geometry>
        <box size=".55 .55 .55"/>
      </geometry>
      <material name="red">
        <color rgba=".8 0 0 1"/>
      </material>
    </visual>
  </link>
  <link name="left_wheel">
    <pose>0.278 0.275 0.1 1.5707 0 1.5707</pose>
    <inertial>
      <mass value="0.0001"/>
      <origin xyz="0 0 0"/>
      <inertia ixx="0.0001" ixy="0.0" ixz="0.0" iyy="0.0001" iyz="0.0" izz="0.0001"/>
    </inertial>
    <collision name="left_wheel_collision">
      <geometry>
        <cylinder length="0.06" radius=".1"/>
      </geometry>
      <surface>
        <friction>
          <ode>
            <mu>0</mu>
            <mu2>0</mu2>
            <slip1>1.0</slip1>
            <slip2>1.0</slip2>
          </ode>
        </friction>
      </surface>
    </collision>
    <visual name="left_wheel_visual">
      <geometry>
        <cylinder length="0.06" radius=".1"/>
      </geometry>
      <material name="red">
        <color rgba=".8 0 0 1"/>
      </material>
    </visual>
  </link>
  <link name="right_wheel">
    <pose>-0.278 0.275 0.1 1.5707 0 1.5707</pose>
    <inertial>
      <mass value="0.0001"/>
      <origin xyz="0 0 0"/>
      <inertia ixx="0.0001" ixy="0.0" ixz="0.0" iyy="0.0001" iyz="0.0" izz="0.0001"/>
    </inertial>
    <collision name="right_wheel_collision">
      <geometry>
        <cylinder length="0.06" radius=".1"/>
      </geometry>
      <surface>
        <friction>
          <ode>
            <mu>0</mu>
            <mu2>0</mu2>
            <slip1>1.0</slip1>
            <slip2>1.0</slip2>
          </ode>
        </friction>
      </surface>
    </collision>
    <visual name="right_wheel_visual">
      <geometry>
        <cylinder length="0.06" radius=".1"/>
      </geometry>
      <material name="red">
        <color rgba=".8 0 0 1"/>
      </material>
    </visual>
  </link>
  <joint name="left_wheel_hinge" type="revolute">
    <pose>0 0.275 0.1 0 0 0</pose>
    <child link="left_wheel"/>
    <parent link="base_link"/>
    <axis xyz="0 1 0"/>
    <limit effort="30" velocity="1.0"/>
    <!--lower="-2.2" upper="0.7"-->
  </joint>
  <joint name="right_wheel_hinge" type="revolute">
    <pose>0 0.275 0.1 0 0 0</pose>
    <child link="right_wheel"/>
    <parent link="base_link"/>
    <axis xyz="0 1 0"/>
    <limit effort="30" velocity="1.0"/>
    <!--lower="-2.2" upper="0.7"-->
  </joint>
  <!-- Kinect frames and mounting (includes simulation)
 <eklavya_kinect/>  -->
</robot>

